Workbook

Sheet Overall Summary
C3: Cash Balance | D3: Cash% | E3: Initial Deposit | F3: Realized Profit | G3: Unrealized Profit | H3: Paid fee | I3: Total | J3: Net Gain | K3: Return | M3: Target | O3: S&P 500
B4: SG Portfolio | C4: ='SG Portfolio'!D11 -> -33411.634 | D4: =C4/I4 -> -1.3361683 | E4: ='SG Portfolio'!D4 -> 23110 | F4: ='SG Portfolio'!G3 -> 6662.8437 | G4: ='SG Portfolio'!M225 -> -4767.286 | H4: ='SG Portfolio'!G5 -> 6156.7367 | I4: =SUM(E4:G4) -> 25005.558 | J4: =I4-E4 -> 1895.5577 | K4: =J4/E4 -> 0.082023266 | M4: =N4/E6 -> 0.19166667 | N4: =E6*COUNT(D11:Z11)/12*M5 -> 6250.25 | O4: Jan 2, 2020 | P4: 3244.67 | R4: Mar 1, 2020 | S4: 2192 | T4: Lowest
B5: FUTU Portfolio | C5: ='FUTU Portfolio'!D13 -> 5239.2215 | D5: =C5/I5 -> 1 | E5: ='FUTU Portfolio'!D6 -> 9500 | F5: ='FUTU Portfolio'!G5 -> -4260.7785 | G5: ='FUTU Portfolio'!M230 -> 0 | H5: ='FUTU Portfolio'!G7 -> 1249.2297 | I5: =SUM(E5:G5) -> 5239.2215 | J5: =I5-E5 -> -4260.7785 | K5: =J5/E5 -> -0.448503 | M5: 0.1 | N5: Annual Goal | O5: Current | P5: 4533 | Q5: =(P5-P4)/P4 -> 0.39706041 | R5: Current | S5: =P5 -> 4533 | T5: =(S5-S4)/S4 -> 1.0679745
B6: Entire Portfolio | C6: =C4+C5 -> -28172.413 | D6: =C6/I6 -> -0.9314802 | E6: =E4+E5 -> 32610 | F6: =F4+F5 -> 2402.0652 | G6: =G4+G5 -> -4767.286 | H6: =H4+H5 -> 7405.9664 | I6: =SUM(E6:G6) -> 30244.779 | J6: =I6-E6 -> -2365.2208 | K6: =J6/E6 -> -0.072530537
D11: 43891 | E11: 43922 | F11: 43952 | G11: 43983 | H11: 44013 | I11: 44044 | J11: 44075 | K11: 44105 | L11: 44136 | M11: 44166 | N11: 44197 | O11: 44228 | P11: 44256 | Q11: 44287 | R11: 44317 | S11: 44348 | T11: 44378 | U11: 44409 | V11: 44440 | W11: 44470 | X11: 44501 | Y11: 44531 | Z11: 44562 | AB11: Total
B12: SG Portfolio | C12: Regular Trade | D12: =SUM('SG Portfolio'!I9) -> 51.02 | E12: =SUM('SG Portfolio'!J9) -> 211.6 | F12: =SUM('SG Portfolio'!K9) -> 221.24 | G12: =SUM('SG Portfolio'!L9) -> 335.9444 | H12: =SUM('SG Portfolio'!M9) -> 177.16831 | I12: =SUM('SG Portfolio'!N9) -> 1068.36 | J12: =SUM('SG Portfolio'!O9) -> 113.36 | K12: =SUM('SG Portfolio'!P9) -> 232.24 | ... M12: =SUM('SG Portfolio'!R9) -> 165.62 | N12: =SUM('SG Portfolio'!S9)-SUM('Day Trade'!E139:E150) -> 626.22229 | O12: =SUM('SG Portfolio'!T9) -> -358.88 | P12: =SUM('SG Portfolio'!U9)-SUM('Day Trade'!E151:E158) -> 1253.07 | Q12: =SUM('SG Portfolio'!V9)-SUM('Day Trade'!E159:E162) -> 1698.91 | R12: =SUM('SG Portfolio'!W9)-'Day Trade'!E163 -> 1028.6518 | S12: =SUM('SG Portfolio'!X9) -> 1944.54 | T12: =SUM('SG Portfolio'!Y9)-SUM('Day Trade'!E164:E172) -> 3176.43 | U12: =SUM('SG Portfolio'!Z9)-SUM('Day Trade'!E173:E180) -> -4689.4895 | V12: =SUM('SG Portfolio'!AA9)-'Day Trade'!E181 -> 179.58 | W12: =SUM('SG Portfolio'!AB9) -> 835.32451 | X12: =SUM('SG Portfolio'!AC9) -> 524.06 | Y12: =SUM('SG Portfolio'!AD9)-'Day Trade'!E182 -> 561.47769 | Z12: =SUM('SG Portfolio'!AE9)-SUM('Day Trade'!E183:E187) -> -4311.1505 | AB12: =SUM(D12:AA12) -> 6081.0605
C13: Day Trade | D13: 0 | E13: 0 | F13: 0 | G13: 0 | H13: 0 | I13: 0 | J13: 0 | K13: 0 | L13: 0 | M13: 0 | N13: =SUM('Day Trade'!E139:E150) -> -1148.4441 | O13: 0 | P13: =SUM('Day Trade'!E151:E158) -> 1503.72 | Q13: =SUM('Day Trade'!E159:E162) -> 331.24 | R13: ='Day Trade'!E163 -> -56.76 | S13: 0 | T13: =SUM('Day Trade'!E164:E172) -> 913.14 | U13: =SUM('Day Trade'!E173:E180) -> 198.1 | V13: ='Day Trade'!E181 -> 113.24 | W13: 0 | X13: 0 | Y13: ='Day Trade'!E182 -> 76.84 | Z13: =SUM('Day Trade'!E183:E187) -> -1349.2927 | AB13: =SUM(D13:AA13) -> 581.78317
C14: Sub-total | D14: =D12+D13 -> 51.02 | E14: =E12+E13 -> 211.6 | F14: =F12+F13 -> 221.24 | G14: =G12+G13 -> 335.9444 | H14: =H12+H13 -> 177.16831 | I14: =I12+I13 -> 1068.36 | J14: =J12+J13 -> 113.36 | K14: =K12+K13 -> 232.24 | ... Z14: =Z12+Z13 -> -5660.4432 | AB14: =SUM(D14:AA14) -> 6662.8437
B15: FUTU Portfolio | C15: Regular Trade | D15: 0 | E15: 0 | F15: 0 | G15: 0 | H15: 0 | I15: 0 | J15: 0 | K15: 0 | L15: 0 | M15: 0 | N15: 0 | O15: 0 | P15: 0 | Q15: 0 | R15: 0 | S15: 0 | T15: ='FUTU Portfolio'!L11 -> -756.03 | U15: ='FUTU Portfolio'!M11 -> 0 | V15: ='FUTU Portfolio'!N11 -> 0 | W15: ='FUTU Portfolio'!O11 -> 125.86 | X15: ='FUTU Portfolio'!P11-SUM('FUTU Portfolio'!L27:L36) -> 86.58 | Y15: ='FUTU Portfolio'!Q11-SUM('FUTU Portfolio'!L37:L43,'FUTU Portfolio'!L45,'FUTU Portfolio'!L47:L52,'FUTU Portfolio'!L54:L56,'FUTU Portfolio'!L63:L64) -> -603.09 | Z15: ='FUTU Portfolio'!R11-SUM('FUTU Portfolio'!L66:L73,'FUTU Portfolio'!L76:L80,'FUTU Portfolio'!L82:L88,'FUTU Portfolio'!L91:L99,'FUTU Portfolio'!L101:'FUTU Portfolio'!L155,'FUTU Portfolio'!L156:L173,'FUTU Portfolio'!L175:L199) -> -2306.14 | AB15: =SUM(D15:AA15) -> -3452.82
C16: Day Trade | D16: 0 | E16: 0 | F16: 0 | G16: 0 | H16: 0 | I16: 0 | J16: 0 | K16: 0 | L16: 0 | M16: 0 | N16: 0 | O16: 0 | P16: 0 | Q16: 0 | R16: 0 | S16: 0 | T16: 0 | U16: 0 | V16: 0 | W16: 0 | X16: =SUM('FUTU Portfolio'!L27:L36) -> 232.19 | Y16: =SUM('FUTU Portfolio'!L37:L43,'FUTU Portfolio'!L45,'FUTU Portfolio'!L47:L52,'FUTU Portfolio'!L54:L56,'FUTU Portfolio'!L63:L64) -> 54.01 | Z16: =SUM('FUTU Portfolio'!L66:L73,'FUTU Portfolio'!L76:L80,'FUTU Portfolio'!L82:L88,'FUTU Portfolio'!L91:L99,'FUTU Portfolio'!L101:'FUTU Portfolio'!L155,'FUTU Portfolio'!L156:L173,'FUTU Portfolio'!L175:L199) -> -1094.1585 | AB16: =SUM(D16:AA16) -> -807.95849
C17: Sub-total | D17: =D15+D16 -> 0 | E17: =E15+E16 -> 0 | F17: =F15+F16 -> 0 | G17: =G15+G16 -> 0 | H17: =H15+H16 -> 0 | I17: =I15+I16 -> 0 | J17: =J15+J16 -> 0 | K17: =K15+K16 -> 0 | ... Z17: =Z15+Z16 -> -3400.2985 | AB17: =SUM(D17:AA17) -> -4260.7785
B18: Entire Portfolio | C18: Regular Trade | D18: =D12+D15 -> 51.02 | E18: =E12+E15 -> 211.6 | F18: =F12+F15 -> 221.24 | G18: =G12+G15 -> 335.9444 | H18: =H12+H15 -> 177.16831 | I18: =I12+I15 -> 1068.36 | J18: =J12+J15 -> 113.36 | K18: =K12+K15 -> 232.24 | ... Z18: =Z12+Z15 -> -6617.2905 | AB18: =SUM(D18:AA18) -> 2628.2405
C19: Day Trade | D19: =D13+D16 -> 0 | E19: =E13+E16 -> 0 | F19: =F13+F16 -> 0 | G19: =G13+G16 -> 0 | H19: =H13+H16 -> 0 | I19: =I13+I16 -> 0 | J19: =J13+J16 -> 0 | K19: =K13+K16 -> 0 | ... Z19: =Z13+Z16 -> -2443.4512 | AB19: =SUM(D19:AA19) -> -226.17531
C20: Sub-total | D20: =D18+D19 -> 51.02 | E20: =E18+E19 -> 211.6 | F20: =F18+F19 -> 221.24 | G20: =G18+G19 -> 335.9444 | H20: =H18+H19 -> 177.16831 | I20: =I18+I19 -> 1068.36 | J20: =J18+J19 -> 113.36 | K20: =K18+K19 -> 232.24 | ... Z20: =Z18+Z19 -> -9060.7417 | AB20: =SUM(D20:AA20) -> 2402.0652
D41: 43891 | E41: 43922 | F41: 43952 | G41: 43983 | H41: 44013 | I41: 44044 | J41: 44075 | K41: 44105 | L41: 44136 | M41: 44166 | N41: 44197 | O41: 44228 | P41: 44256 | Q41: 44287 | R41: 44317 | S41: 44348 | T41: 44378 | U41: 44409 | V41: 44440 | W41: 44470 | X41: 44501 | Y41: 44531 | Z41: 44562
C42: Hang Seng | D42: 23603 | E42: 24643 | F42: 22961 | G42: 24427 | H42: 24595 | I42: 25177 | J42: 23459 | K42: 24107 | L42: 26341 | M42: 27231 | N42: 28283 | O42: 28980 | P42: 28378 | Q42: 28724 | R42: 29151 | S42: 28827 | T42: 25961 | U42: 25878 | V42: 24575 | W42: 25377 | X42: 23475 | Y42: 23397 | Z42: 24429
C43: DJI | D43: 24345 | E43: 25383 | F43: 25812 | G43: 26428 | H43: 28430 | I43: 27781 | J43: 26501 | K43: 29638 | L43: 30606 | M43: 29982 | N43: 30932 | O43: 32981 | P43: 33874 | Q43: 34529 | R43: 34502 | S43: 34935 | T43: 35360 | U43: 33843 | V43: 35819 | W43: 34483 | X43: 36338 | Y43: 36113 | Z43: 36113
C44: NASDAQ | D44: 8889 | E44: 3489 | F44: 10058 | G44: 10745 | H44: 11775 | I44: 11167 | J44: 10911 | K44: 12198 | L44: 12888 | M44: 13070 | N44: 13192 | O44: 13246 | P44: 13962 | Q44: 13748 | R44: 14503 | S44: 14672 | T44: 15259 | U44: 14448 | V44: 15498 | W44: 15537 | X44: 15644 | Y44: 14806 | Z44: 14806
C45: S&P 500 | D45: 2912 | E45: 3044 | F45: 3100 | G45: 3271 | H45: 3500 | I45: 3363 | J45: 3269 | K45: 3621 | L45: 3756 | M45: 3714 | N45: 3811 | O45: 3972 | P45: 4181 | Q45: 4204 | R45: 4297 | S45: 4395 | T45: 4522 | U45: 4307 | V45: 4605 | W45: 4567 | X45: 4766 | Y45: 4659 | Z45: 4659

Sheet SG Portfolio
F2: Return
C3: Total Cash | D3: =D4+D5 -> 29772.844 | E3: Realized | F3: =G3/D4 -> 0.28830998 | G3: =AF15 -> 6662.8437 | H3: =G3/(G3+G5) -> 0.51973961 | J3: Target | L3: S&P 500
C4: Initial Deposit | D4: =4290+12110+6110+10610+3490-7000-3000-3500 -> 23110 | E4: Overall | F4: =G4/D4 -> 0.082023266 | G4: =G3+H20 -> 1895.5577 | H4: =G4/(G4+G5) -> 0.23540591 | J4: =K4/D4 -> 0.19166667 | K4: =D4*COUNT(I8:AE8)/12*J5 -> 4429.4167 | L4: Jan 2, 2020 | M4: 3244.67 | O4: Mar 1, 2020 | P4: 2192 | Q4: Lowest
C5: Realized Profit | D5: =G3 -> 6662.8437 | E5: Total paid fee | G5: =Table2[[#Totals],[Fee]]+'Day Trade'!J129+(308.12+122.12+96.9+204.1+144.28+91.68+232.1+140.27+106.68/7.7+7.44+34) -> 6156.7367 | H5: =G5/(G3+G5) -> 0.48026039 | J5: ='Overall Summary'!M5 -> 0.1 | K5: Annual Goal | L5: Current | M5: ='Overall Summary'!P5 -> 4533 | N5: =(M5-M4)/M4 -> 0.39706041 | O5: Current | P5: =M5 -> 4533 | Q5: =(P5-P4)/P4 -> 1.0679745
C8: Investment | D8: =D9+D10 -> 63184.478 | E8: =D8/D3 -> 2.1222184 | H8: Realized | I8: 43891 | J8: 43922 | K8: 43952 | L8: 43983 | M8: 44013 | N8: 44044 | O8: 44075 | P8: 44105 | Q8: 44136 | R8: 44166 | S8: 44197 | T8: 44228 | U8: 44256 | V8: 44287 | W8: 44317 | X8: 44348 | Y8: 44378 | Z8: 44409 | AA8: 44440 | AB8: 44470 | AC8: 44501 | AD8: 44531 | AE8: 44562
C9: HKEx | D9: =+$K$210+$K$214 -> 3618.7981 | E9: =D9/$D$8 -> 0.05727353 | H9: P/L (USD) | I9: =L31+L32+L33 -> 51.02 | J9: =L35+L36 -> 211.6 | K9: =L38 -> 221.24 | L9: =L39+L30 -> 335.9444 | M9: =L40+L41+L34 -> 177.16831 | N9: =L37+L42+L43+L46 -> 1068.36 | O9: =L44+L45+L48+L47 -> 113.36 | P9: =L49 -> 232.24 | Q9: =L50+L51+L52+L53+L54+L55+L56+L57+L58+L59 -> 1035.7615 | R9: =L60+L61+L62 -> 165.62 | S9: =L63+L64+L65+L66+L67+L68+L69+L70+L71+L72+L73+L74+L75+L76+L77+L78+L79+SUM('Day Trade'!E139:E150) -> -522.22181 | T9: =-308.12+L80 -> -358.88 | U9: =-122.12+SUM('Day Trade'!E151:E158)+SUM(L81:L100) -> 2756.79 | V9: =-96.9-(36.48+7.51)+L101+L102+L103+L104+L105+L106+L107+SUM('Day Trade'!E159:E162) -> 2030.15 | W9: =-204.1+L108+L109+L110+L111+'Day Trade'!E163 -> 971.89178 | X9: =-144.28+L112+L113+L114+L115+L116+L117 -> 1944.54 | Y9: =-91.68+L118+L119+L120+L121+L122+L123+L124+L125+L126+L127+L128+L129+L130+SUM('Day Trade'!E164:E172) -> 4089.57 | Z9: =-86.07+L131+L132+L133+L134+L135+L136+L137+L138+L139+L140+L141+L142+SUM('Day Trade'!E173:E180) -> -4491.3895 | AA9: =-232.1+L143+L144+L145+L146+L147+L148+L149+'Day Trade'!E181 -> 292.82 | AB9: =-140.27-106.68/7.7-7.44-34+L150+L151+L152+L153+L154+L155+L156+L157+L158+L159+L160+L161+L162+L163+L164 -> 835.32451 | AC9: =-2.38+L165+L166+L167+L168+L169 -> 524.06 | AD9: =-23.95+L170+L171+L172+L173+L174+'Day Trade'!E182 -> 638.31769 | AE9: =-11.83-(7.45+34)+SUM(L175:L202)+SUM('Day Trade'!E183:E187) -> -5660.4432
C10: USEx | D10: =+$K$212+$K$216+$K$218+$K$220 -> 59565.68 | E10: =D10/$D$8 -> 0.94272647 | J10: =IF(J9=0,0,(J9-I9)/I9) -> 3.1473932 | K10: =IF(K9=0,0,(K9-J9)/J9) -> 0.045557656 | L10: =IF(L9=0,0,(L9-K9)/K9) -> 0.51846139 | M10: =IF(M9=0,0,(M9-L9)/L9) -> -0.47262611 | N10: =IF(N9=0,0,(N9-M9)/M9) -> 5.0301982 | O10: =IF(O9=0,0,(O9-N9)/N9) -> -0.89389344 | P10: =IF(P9=0,0,(P9-O9)/O9) -> 1.0486944 | Q10: =IF(Q9=0,0,(Q9-P9)/P9) -> 3.4598757 | ... S10: =IF(S9=0,0,(S9-R9)/R9) -> -4.1531325 | T10: =IF(T9=0,0,(S9-T9)/S9) -> 0.31278243 | U10: =IF(U9=0,0,(T9-U9)/T9) -> 8.6816485 | V10: =IF(V9=0,0,(V9-U9)/U9) -> -0.26358192 | W10: =IF(W9=0,0,(W9-V9)/V9) -> -0.52127095 | X10: =IF(X9=0,0,(X9-W9)/W9) -> 1.0007783 | Y10: =IF(Y9=0,0,(Y9-X9)/X9) -> 1.1031041 | Z10: =IF(Z9=0,0,(Z9-Y9)/Y9) -> -2.0982547 | AA10: =IF(AA9=0,0,(AA9-Z9)/Z9) -> -1.0651959 | AB10: =IF(AB9=0,0,(AB9-AA9)/AA9) -> 1.8526894 | AC10: =IF(AC9=0,0,(AC9-AB9)/AB9) -> -0.37262706 | ... AE10: =IF(AE9=0,0,(AE9-AD9)/AD9) -> -9.8677524
C11: Cash Balance | D11: =D3-D8 -> -33411.634 | E11: =D11/D3 -> -1.1222184 | Q11: sub-total | R11: =SUM(I9:R9) -> 3612.3142 | AC11: sub-total | AD11: =SUM(S9:AD9) -> 8710.9727 | AE11: sub-total | AF11: =SUM(AE9) -> -5660.4432
C12: Margin | D12: =IF(D11<0,-D11,0) -> 33411.634 | E12: =TODAY()-1 -> 44648 | Q12: average month | R12: =AVERAGE(I9:R9) -> 361.23142 | AC12: average month | AD12: =AVERAGE(S9:AD9) -> 725.91439 | AE12: average month | AF12: =AVERAGE(AE9) -> -5660.4432
C13: Margin Interest | D13: =E13*'Fee and Margin'!I5 -> 6.4967067 | E13: =TODAY()-E12 -> 1 | Q13: sub-total gain | R13: 0.10906746 | AC13: sub-total gain | AD13: =AD11/D4 -> 0.37693521 | AE13: sub-total gain | AF13: =AF11/$D$4 -> -0.2449348
AE15: Total | AF15: =SUM(I9:AE9) -> 6662.8437
D16: Grade | E16: Amount | F16: Composition | G16: Unrealized P/L | J16: Return | K16: Realized Gain/Loss | L16: Exit Transactions | AE16: Monthly | AF16: =AF15/COUNT(I8:AD8) -> 302.85653
C17: Risk Profile | D17: A | E17: =+K214+K216+K210+K218 -> 39065.198 | F17: =E17/D8 -> 0.61827207 | G17: =IF(E17=0,0,H17/E17) -> 0.08941447 | H17: =+M214+M216+M210+M218 -> 3492.994 | J17: <5% | K17: =L30+L34+L36+L40+L44+L56+L58+L64+L68+L71+L73+L74+L83+L89+L90+L91+L92+L95+L96+L97+L100+L104+L106+L111+L113+L115+L116+L120+L121+L122+L123+L124+L127+L128+L129+'Day Trade'!E137 -> 3926.8368 | L17: 35 | M17: =L17/$L$21 -> 0.34653465 | AE17: Total gain | AF17: =SUM(I9:AE9)/$D$4 -> 0.28830998
D18: B | E18: =+K212+K220 -> 24119.28 | F18: =E18/D8 -> 0.38172793 | G18: =IF(E18=0,0,H18/E18) -> -0.34247623 | H18: =+M212+M220 -> -8260.28 | J18: >=5% | K18: =L32+L33+L35+L37+L38+L39+L41+L42+L43+L45+L46+L49+L50+L51+L52+L53+L54+L55+L57+L59+L60+L61+L62+L63+L65+L66+L67+L69+L70+L72+L76+L82+L93+L101+L102+L103+L107+L108+L112+L114+L117+L118+L119+L125+L130 -> 13577.643 | L18: 45 | M18: =L18/$L$21 -> 0.44554455
D19: C | E19: 0 | F19: =E19/D8 -> 0 | G19: =IF(E19=0,0,H19/E19) -> 0 | H19: 0 | J19: <0% | K19: =L31+L47+L75+L48+L77+L78+L79+L80+L81+L84+L85+L86+L87+L88+L94+L98+L99+L105+L109+L110+L126 -> -2930.2482 | L19: 21 | M19: =L19/$L$21 -> 0.20792079
D20: Total | E20: =SUM(E17:E19) -> 63184.478 | F20: =SUM(F17:F19) -> 1 | G20: =IF(E20=0,0,H20/E20) -> -0.075450272 | H20: =SUM(H17:H19) -> -4767.286 | J20: Interest expense | K20: =-308.12-122.12-96.9-(36.48+7.51)-204.1-144.28-91.68 -> -1011.19
H21: =H20/E20 -> -0.075450272 | J21: Total | K21: =SUM(K17:K20) -> 13563.041 | L21: =SUM(L17:L19) -> 101 | M21: =SUM(M17:M19) -> 1
D23: China Co. | E23: =+K212+K210+K214 -> 10831.318 | F23: =E23/(E23+E24) -> 0.23405039 | G23: =+M212+M210+M214 -> -4048.036 | H23: =IF(E23=0,0,G23/E23) -> -0.37373439 | J23: China Co. | K23: 3353.0583 | L23: 17 | M23: =K23/$K$25 -> 0.23946845
D24: US Co. | E24: =K216+K218 -> 35446.4 | F24: =E24/(E23+E24) -> 0.76594961 | G24: =M216+M218 -> 4570.51 | H24: =IF(E24=0,0,G24/E24) -> 0.12894144 | J24: US Co. | K24: 10649.03 | L24: 27 | M24: =K24/$K$25 -> 0.76053155
E25: =SUM(E23:E24) -> 46277.718 | F25: =SUM(F23:F24) -> 1 | G25: =SUM(G23:G24) -> 522.47397 | H25: =IF(E25=0,0,G25/E25) -> 0.011289968 | J25: Total | K25: =SUM(K23:K24) -> 14002.088 | M25: =SUM(M23:M24) -> 1
B28: Historical Transactions
B29: No. | C29: Stock Name | D29: Market | E29: Currency | F29: Buy Price | G29: Quantity | H29: Fee | I29: Average Price | J29: Investment | K29: Current Price | L29: Gain/Loss | M29: P/L % | N29: Exit Price | O29: Open Date | P29: Close Date | Q29: Holding Days
B30: 1 | C30: #VALUE! | D30: HK | E30: HKD | F30: 216 | G30: 100 | H30: =(I30-F30)*G30*2/7.73 -> 27.337646 | I30: 217.0566 | J30: =I30*G30 -> 21705.66 | K30: {=_FV(C30,"Price")} -> 113.5 | L30: =(N30-I30)*G30/7.73 -> 12.204398 | M30: =L30*7.8/J30 -> 0.0043856905 | N30: 218 | O30: 43885 | P30: 44004 | Q30: =Table2[[#This Row],[Close Date]]-Table2[[#This Row],[Open Date]] -> 119
B31: 2 | C31: #VALUE! | D31: NASDAQ | E31: USD | F31: 55.07 | G31: 10 | H31: 21.76 | I31: =((F31*G31)+H31)/G31 -> 57.246 | J31: =I31*G31 -> 572.46 | K31: {=_FV(C31,"Price")} -> 120.24 | L31: =(N31-I31)*G31 -> -105.46 | M31: =L31/J31 -> -0.18422248 | N31: 46.7 | O31: 43886 | P31: 43916 | Q31: =Table2[[#This Row],[Close Date]]-Table2[[#This Row],[Open Date]] -> 30
B32: 3 | C32: #VALUE! | D32: NASDAQ | E32: USD | F32: 85 | G32: 10 | H32: =10.88*2 -> 21.76 | I32: =((F32*G32)+H32)/G32 -> 87.176 | J32: =I32*G32 -> 871.76 | K32: {=_FV(C32,"Price")} -> 138.72 | L32: =(N32-I32)*G32 -> 48.24 | M32: =L32/J32 -> 0.055336331 | N32: 92 | O32: 43909 | P32: 43913 | Q32: =Table2[[#This Row],[Close Date]]-Table2[[#This Row],[Open Date]] -> 4
B33: 4 | C33: #VALUE! | D33: NASDAQ | E33: USD | F33: 47 | G33: 20 | H33: =10.88*2 -> 21.76 | I33: =((F33*G33)+H33)/G33 -> 48.088 | J33: =I33*G33 -> 961.76 | K33: {=_FV(C33,"Price")} -> 51.51 | L33: =(N33-I33)*G33 -> 108.24 | M33: =L33/J33 -> 0.11254367 | N33: 53.5 | O33: 43910 | P33: 43916 | Q33: =Table2[[#This Row],[Close Date]]-Table2[[#This Row],[Open Date]] -> 6
B34: 5 | C34: #VALUE! | D34: HK | E34: HKD | F34: 2.8 | G34: 1000 | H34: =85.22*2/7.73 -> 22.049159 | I34: 2.97 | J34: =I34*G34 -> 2970 | K34: {=_FV(C34,"Price")} -> 3.05 | L34: =(N34-I34)*G34/7.73 -> 6.4683053 | M34: =L34*7.8/J34 -> 0.016987468 | N34: 3.02 | O34: 43913 | P34: 44019 | Q34: =Table2[[#This Row],[Close Date]]-Table2[[#This Row],[Open Date]] -> 106
B35: 6 | C35: #VALUE! | D35: NASDAQ | E35: USD | F35: 65.7 | G35: 20 | H35: =10.88*2 -> 21.76 | I35: =((F35*G35)+H35)/G35 -> 66.788 | J35: =I35*G35 -> 1335.76 | K35: {=_FV(C35,"Price")} -> 158.45 | L35: =(N35-I35)*G35 -> 116.24 | M35: =L35/J35 -> 0.087021621 | N35: 72.6 | O35: 43915 | P35: 43930 | Q35: =Table2[[#This Row],[Close Date]]-Table2[[#This Row],[Open Date]] -> 15
B36: 7 | C36: #VALUE! | D36: NASDAQ | E36: USD | F36: =(156*10+194*2)/12 -> 162.33333 | G36: 12 | H36: =10.88*3 -> 32.64 | I36: =((F36*G36)+H36)/G36 -> 165.05333 | J36: =I36*G36 -> 1980.64 | K36: {=_FV(C36,"Price")} -> 223.59 | L36: =(N36-I36)*G36 -> 95.36 | M36: =L36/J36 -> 0.048146054 | N36: 173 | O36: 43915 | P36: 43930 | Q36: =Table2[[#This Row],[Close Date]]-Table2[[#This Row],[Open Date]] -> 15
B37: 8 | C37: #VALUE! | D37: NYSE | E37: USD | F37: =(185+174.5)/2 -> 179.75 | G37: 10 | H37: =10.88*2 -> 21.76 | I37: =((F37*G37)+H37)/G37 -> 181.926 | J37: =I37*G37 -> 1819.26 | K37: {=_FV(C37,"Price")} -> 359.57 | L37: =(N37-I37)*G37 -> 310.74 | M37: =L37/J37 -> 0.17080571 | N37: 213 | O37: 43945 | P37: 44060 | Q37: =Table2[[#This Row],[Close Date]]-Table2[[#This Row],[Open Date]] -> 115
B38: 9 | C38: #VALUE! | D38: NYSE | E38: USD | F38: 105.8 | G38: 15 | H38: =10.88*2 -> 21.76 | I38: =((F38*G38)+H38)/G38 -> 107.25067 | J38: =I38*G38 -> 1608.76 | K38: {=_FV(C38,"Price")} -> 138.72 | L38: =(N38-I38)*G38 -> 221.24 | M38: =L38/J38 -> 0.13752207 | N38: 122 | O38: 43977 | P38: 43979 | Q38: =Table2[[#This Row],[Close Date]]-Table2[[#This Row],[Open Date]] -> 2
B39: 10 | C39: #VALUE! | D39: NYSE | E39: USD | F39: 27.5 | G39: 50 | H39: =8.88*2 -> 17.76 | I39: =((F39*G39)+H39)/G39 -> 27.8552 | J39: =I39*G39 -> 1392.76 | K39: {=_FV(C39,"Price")} -> 55.93 | L39: =(N39-I39)*G39 -> 323.74 | M39: =L39/J39 -> 0.23244493 | N39: 34.33 | O39: 43991 | P39: 43993 | Q39: =Table2[[#This Row],[Close Date]]-Table2[[#This Row],[Open Date]] -> 2
B40: 11 | C40: #VALUE! | D40: NYSE | E40: USD | F40: =(57.5*20+48*25)/(20+25) -> 52.222222 | G40: =20+25 -> 45 | H40: =8.88*3 -> 26.64 | I40: =((F40*G40)+H40)/G40 -> 52.814222 | J40: =I40*G40 -> 2376.64 | K40: {=_FV(C40,"Price")} -> 78.54 | L40: =(N40-I40)*G40 -> 88.46 | M40: =L40/J40 -> 0.037220614 | N40: 54.78 | O40: 43999 | P40: 44029 | Q40: =Table2[[#This Row],[Close Date]]-Table2[[#This Row],[Open Date]] -> 30
B41: 12 | C41: #VALUE! | D41: NASDAQ | E41: USD | F41: 228 | G41: 5 | H41: =8.88*2 -> 17.76 | I41: =((F41*G41)+H41)/G41 -> 231.552 | J41: =I41*G41 -> 1157.76 | K41: {=_FV(C41,"Price")} -> 223.59 | L41: =(N41-I41)*G41 -> 82.24 | M41: =L41/J41 -> 0.07103372 | N41: 248 | O41: 44008 | P41: 44027 | Q41: =Table2[[#This Row],[Close Date]]-Table2[[#This Row],[Open Date]] -> 19
B42: 13 | C42: #VALUE! | D42: NASDAQ | E42: USD | F42: 16.68 | G42: 80 | H42: =8.88*2 -> 17.76 | I42: =((F42*G42)+H42)/G42 -> 16.902 | J42: =I42*G42 -> 1352.16 | K42: {=_FV(C42,"Price")} -> 26.48 | L42: =(N42-I42)*G42 -> 200.64 | M42: =L42/J42 -> 0.14838481 | N42: 19.41 | O42: 44043 | P42: 44054 | Q42: =Table2[[#This Row],[Close Date]]-Table2[[#This Row],[Open Date]] -> 11
B43: 14 | C43: #VALUE! | D43: NASDAQ | E43: USD | F43: 15 | G43: 40 | H43: =8.88*2 -> 17.76 | I43: =((F43*G43)+H43)/G43 -> 15.444 | J43: =I43*G43 -> 617.76 | K43: {=_FV(C43,"Price")} -> 26.48 | L43: =(N43-I43)*G43 -> 202.24 | M43: =L43/J43 -> 0.32737633 | N43: 20.5 | O43: 44056 | P43: 44071 | Q43: =Table2[[#This Row],[Close Date]]-Table2[[#This Row],[Open Date]] -> 15
B44: 15 | C44: #VALUE! | D44: NASDAQ | E44: USD | F44: 15 | G44: 40 | H44: =8.88*2 -> 17.76 | I44: =((F44*G44)+H44)/G44 -> 15.444 | J44: =I44*G44 -> 617.76 | K44: {=_FV(C44,"Price")} -> 26.48 | L44: =(N44-I44)*G44 -> 16.64 | M44: =L44/J44 -> 0.026936027 | N44: 15.86 | O44: 44056 | P44: 44084 | Q44: =Table2[[#This Row],[Close Date]]-Table2[[#This Row],[Open Date]] -> 28
B45: 16 | C45: #VALUE! | D45: NASDAQ | E45: USD | F45: 350 | G45: 2 | H45: =8.88*2 -> 17.76 | I45: =((F45*G45)+H45)/G45 -> 358.88 | J45: =I45*G45 -> 717.76 | K45: {=_FV(C45,"Price")} -> 1091.84 | L45: =(N45-I45)*G45 -> 202.24 | M45: =L45/J45 -> 0.28176549 | N45: 460 | O45: 44082 | P45: 44091 | Q45: =Table2[[#This Row],[Close Date]]-Table2[[#This Row],[Open Date]] -> 9
B46: 17 | C46: #VALUE! | D46: NYSE | E46: USD | F46: =(185+174.5)/2 -> 179.75 | G46: 10 | H46: =8.88*2 -> 17.76 | I46: =((F46*G46)+H46)/G46 -> 181.526 | J46: =I46*G46 -> 1815.26 | K46: {=_FV(C46,"Price")} -> 359.57 | L46: =(N46-I46)*G46 -> 354.74 | M46: =L46/J46 -> 0.19542104 | N46: 217 | O46: 43945 | P46: 44074 | Q46: =Table2[[#This Row],[Close Date]]-Table2[[#This Row],[Open Date]] -> 129
B47: 18 | C47: #VALUE! | D47: NASDAQ | E47: USD | F47: 49.5 | G47: 15 | H47: =8.88*2 -> 17.76 | I47: =((F47*G47)+H47)/G47 -> 50.684 | J47: =I47*G47 -> 760.26 | K47: {=_FV(C47,"Price")} -> 51.51 | L47: =(N47-I47)*G47 -> -17.76 | M47: =L47/J47 -> -0.023360429 | N47: 49.5 | O47: 44036 | P47: 44103 | Q47: =Table2[[#This Row],[Close Date]]-Table2[[#This Row],[Open Date]] -> 67
...

Sheet FUTU Portfolio
C3: ACCOUNT BALANCE | D3: =D6+G6 -> 5239.2215
F4: Return
C5: Total Cash | D5: =D6+D7 -> 5239.2215 | E5: Realized | F5: =G5/D6 -> -0.448503 | G5: =R13 -> -4260.7785 | H5: =G5/(G5+G7) -> 1.4148131 | J5: Target | L5: S&P 500
C6: Initial Deposit | D6: =3000+2000+4500 -> 9500 | E6: Overall | F6: =G6/D6 -> -0.448503 | G6: =G5+M230 -> -4260.7785 | H6: =G6/(G6+G7) -> 1.4148131 | J6: =K6/D6 -> 0.083333333 | K6: =D6*COUNT(I10:R10)/12*J7 -> 791.66667 | L6: Jan 2, 2020 | M6: 3244.67 | O6: Mar 1, 2020 | P6: 2192 | Q6: Lowest
C7: Realized Profit | D7: =G5 -> -4260.7785 | E7: Total paid fee | G7: =Table29[[#Totals],[Fee]]+I230 -> 1249.2297 | H7: =G7/(G5+G7) -> -0.41481306 | J7: ='Overall Summary'!M5 -> 0.1 | K7: Annual Goal | L7: Current | M7: ='Overall Summary'!P5 -> 4533 | N7: =(M7-M6)/M6 -> 0.39706041 | O7: Current | P7: =M7 -> 4533 | Q7: =(P7-P6)/P6 -> 1.0679745
C10: Investment | D10: =D11+D12 -> 0 | E10: =D10/D5 -> 0 | H10: Realized | I10: 44287 | J10: 44317 | K10: 44348 | L10: 44378 | M10: 44409 | N10: 44440 | O10: 44470 | P10: 44501 | Q10: 44531 | R10: 44562
C11: HKEx | D11: 0 | E11: 0 | H11: P/L (USD) | I11: 0 | J11: 0 | K11: 0 | L11: =L20 -> -756.03 | M11: 0 | N11: 0 | O11: =L22+L23 -> 125.86 | P11: {=SUM(L21+L24+L25+L26+L27+L28:L36)} -> 318.77 | Q11: =SUM(L37:L64) -> -549.08 | R11: =-350/7+SUM(L65:L210) -> -3400.2985
C12: USEx | D12: =+$K$218+$K$220+$K$222+$K$224 -> 0 | E12: =D12/$D$10 -> #DIV/0! | I12: =IF(I11=0,0,(I11-#REF!)/#REF!) -> 0 | J12: =IF(J11=0,0,(J11-I11)/I11) -> 0 | K12: =IF(K11=0,0,(K11-J11)/J11) -> 0 | L12: =IF(L11=0,0,(L11-K11)/K11) -> #DIV/0! | M12: =IF(M11=0,0,(M11-L11)/L11) -> 0 | N12: =IF(N11=0,0,(N11-M11)/M11) -> 0 | O12: =IF(O11=0,0,(O11-N11)/N11) -> #DIV/0! | P12: =IF(P11=0,0,(P11-O11)/O11) -> 1.5327348 | Q12: =IF(Q11=0,0,(Q11-P11)/P11) -> -2.7224958 | R12: =IF(R11=0,0,(R11-Q11)/Q11) -> 5.1927196
C13: Cash Balance | D13: =D5-D10 -> 5239.2215 | E13: =D13/D5 -> 1 | Q13: sub-total | R13: =SUM(I11:R11) -> -4260.7785
C14: Margin | D14: =IF(D13<0,-D13,0) -> 0 | E14: =TODAY()-1 -> 44648 | Q14: average month | R14: =AVERAGE(I11:R11) -> -426.07785
C15: Margin Interest | D15: =E15*D14*4.85%/360 -> 0 | E15: =TODAY()-E14 -> 1 | Q15: sub-total gain | R15: =R13/$D$6 -> -0.448503
B18: Historical Transactions
B19: No. | C19: Stock Name | D19: Market | E19: Currency | F19: Buy Price | G19: Quantity | H19: Fee | I19: Average Price | J19: Investment | K19: Current Price | L19: Gain/Loss | M19: P/L % | N19: Exit Price | O19: Open Date | P19: Close Date | Q19: Holding Days
B20: 1 | C20: #VALUE! | D20: NASDAQ | E20: USD | F20: 6.91 | G20: 142 | H20: =2.42+2.43 -> 4.85 | I20: =((F20*G20)+H20)/G20 -> 6.9441549 | J20: =I20*G20 -> 986.07 | K20: {=_FV(C20,"Price")} -> 2.8 | L20: =(N20-I20)*G20 -> -756.03 | M20: =L20/J20 -> -0.76671027 | N20: 1.62 | O20: 44313 | P20: 44400 | Q20: =Table29[[#This Row],[Close Date]]-Table29[[#This Row],[Open Date]] -> 87
B21: 3 | C21: #VALUE! | D21: OTC | E21: USD | F21: 62 | G21: 10 | H21: =2.02+2.04 -> 4.06 | I21: =((F21*G21)+H21)/G21 -> 62.406 | J21: =I21*G21 -> 624.06 | K21: {=_FV(C21,"Price")} -> 47.42 | L21: =(N21-I21)*G21 -> 0.94 | M21: =L21/J21 -> 0.0015062654 | N21: 62.5 | O21: 44406 | P21: 44518 | Q21: =Table29[[#This Row],[Close Date]]-Table29[[#This Row],[Open Date]] -> 112
B22: 4 | C22: #VALUE! | D22: NASDAQ | E22: USD | F22: 155 | G22: 6 | H22: =2.01+2.03 -> 4.04 | I22: =((F22*G22)+H22)/G22 -> 155.67333 | J22: =I22*G22 -> 934.04 | K22: {=_FV(C22,"Price")} -> 156.5 | L22: =(N22-I22)*G22 -> 8.02 | M22: =L22/J22 -> 0.008586356 | N22: 157.01 | O22: 44449 | P22: 44470 | Q22: =Table29[[#This Row],[Close Date]]-Table29[[#This Row],[Open Date]] -> 21
B23: 5 | C23: #VALUE! | D23: NYSE | E23: USD | F23: 151.81 | G23: 10 | H23: =2.02+2.04 -> 4.06 | I23: =((F23*G23)+H23)/G23 -> 152.216 | J23: =I23*G23 -> 1522.16 | K23: {=_FV(C23,"Price")} -> 115.09 | L23: =(N23-I23)*G23 -> 117.84 | M23: =L23/J23 -> 0.077416303 | N23: 164 | O23: 44459 | P23: 44481 | Q23: =Table29[[#This Row],[Close Date]]-Table29[[#This Row],[Open Date]] -> 22
B24: 8 | C24: #VALUE! | D24: NYSE | E24: USD | F24: 6.35 | G24: 100 | H24: =2.29+2.31 -> 4.6 | I24: =((F24*G24)+H24)/G24 -> 6.396 | J24: =I24*G24 -> 639.6 | K24: {=_FV(C24,"Price")} -> 6 | L24: =(N24-I24)*G24 -> 43.4 | M24: =L24/J24 -> 0.067854909 | N24: 6.83 | O24: 44503 | P24: 44518 | Q24: =Table29[[#This Row],[Close Date]]-Table29[[#This Row],[Open Date]] -> 15
B25: 9 | C25: #VALUE! | D25: NASDAQ | E25: USD | F25: 36.5 | G25: 10 | H25: =2.02+2.04 -> 4.06 | I25: =((F25*G25)+H25)/G25 -> 36.906 | J25: =I25*G25 -> 369.06 | K25: {=_FV(C25,"Price")} -> 28.99 | L25: =(N25-I25)*G25 -> -19.06 | M25: =L25/J25 -> -0.051644719 | N25: 35 | O25: 44512 | P25: 44529 | Q25: =Table29[[#This Row],[Close Date]]-Table29[[#This Row],[Open Date]] -> 17
B26: 10 | C26: #VALUE! | D26: NYSE | E26: USD | F26: 55 | G26: 10 | H26: =2.02+2.04 -> 4.06 | I26: =((F26*G26)+H26)/G26 -> 55.406 | J26: =I26*G26 -> 554.06 | K26: {=_FV(C26,"Price")} -> 27.01 | L26: =(N26-I26)*G26 -> -34.06 | M26: =L26/J26 -> -0.061473487 | N26: 52 | O26: 44518 | P26: 44530 | Q26: =Table29[[#This Row],[Close Date]]-Table29[[#This Row],[Open Date]] -> 12
B27: 11 | C27: #VALUE! | D27: NYSE | E27: USD | F27: 54 | G27: 50 | H27: =2.14+2.16 -> 4.3 | I27: =((F27*G27)+H27)/G27 -> 54.086 | J27: =I27*G27 -> 2704.3 | K27: {=_FV(C27,"Price")} -> 27.13 | L27: =(N27-I27)*G27 -> 20.7 | M27: =L27/J27 -> 0.0076544762 | N27: 54.5 | O27: 44524 | P27: 44524 | Q27: =Table29[[#This Row],[Close Date]]-Table29[[#This Row],[Open Date]] -> 0
B28: 12 | C28: #VALUE! | D28: NYSE | E28: USD | F28: 50.8 | G28: 50 | H28: =2.14+2.16 -> 4.3 | I28: =((F28*G28)+H28)/G28 -> 50.886 | J28: =I28*G28 -> 2544.3 | K28: {=_FV(C28,"Price")} -> 27.13 | L28: =(N28-I28)*G28 -> 65.7 | M28: =L28/J28 -> 0.025822427 | N28: 52.2 | O28: 44526 | P28: 44526 | Q28: =Table29[[#This Row],[Close Date]]-Table29[[#This Row],[Open Date]] -> 0
B29: 13 | C29: #VALUE! | D29: NYSE | E29: USD | F29: 295 | G29: 10 | H29: =2.02+2.05 -> 4.07 | I29: =((F29*G29)+H29)/G29 -> 295.407 | J29: =I29*G29 -> 2954.07 | K29: {=_FV(C29,"Price")} -> 116.98 | L29: =(N29-I29)*G29 -> 23.93 | M29: =L29/J29 -> 0.0081006882 | N29: 297.8 | O29: 44526 | P29: 44526 | Q29: =Table29[[#This Row],[Close Date]]-Table29[[#This Row],[Open Date]] -> 0
B30: 14 | C30: #VALUE! | D30: NASDAQ | E30: USD | F30: 170 | G30: 20 | H30: =2.05+2.08 -> 4.13 | I30: =((F30*G30)+H30)/G30 -> 170.2065 | J30: =I30*G30 -> 3404.13 | K30: {=_FV(C30,"Price")} -> 156.5 | L30: =(N30-I30)*G30 -> 1.87 | M30: =L30/J30 -> 0.00054933272 | N30: 170.3 | O30: 44526 | P30: 44526 | Q30: =Table29[[#This Row],[Close Date]]-Table29[[#This Row],[Open Date]] -> 0
B31: 15 | C31: #VALUE! | D31: NYSE | E31: USD | F31: 39.9 | G31: 60 | H31: =2.17+2.19 -> 4.36 | I31: =((F31*G31)+H31)/G31 -> 39.972667 | J31: =I31*G31 -> 2398.36 | K31: {=_FV(C31,"Price")} -> 21.21 | L31: =(N31-I31)*G31 -> 13.64 | M31: =L31/J31 -> 0.0056872196 | N31: 40.2 | O31: 44526 | P31: 44526 | Q31: =Table29[[#This Row],[Close Date]]-Table29[[#This Row],[Open Date]] -> 0
B32: 16 | C32: #VALUE! | D32: NASDAQ | E32: USD | F32: 34.5 | G32: 90 | H32: =2.26+2.29 -> 4.55 | I32: =((F32*G32)+H32)/G32 -> 34.550556 | J32: =I32*G32 -> 3109.55 | K32: {=_FV(C32,"Price")} -> 26.48 | L32: =(N32-I32)*G32 -> 103.45 | M32: =L32/J32 -> 0.033268479 | N32: 35.7 | O32: 44529 | P32: 44529 | Q32: =Table29[[#This Row],[Close Date]]-Table29[[#This Row],[Open Date]] -> 0
B33: 17 | C33: #VALUE! | D33: NASDAQ | E33: USD | F33: 71.5 | G33: 50 | H33: =2.14+2.17 -> 4.31 | I33: =((F33*G33)+H33)/G33 -> 71.5862 | J33: =I33*G33 -> 3579.31 | K33: {=_FV(C33,"Price")} -> 43.67 | L33: =(N33-I33)*G33 -> 18.19 | M33: =L33/J33 -> 0.0050819851 | N33: 71.95 | O33: 44529 | P33: 44529 | Q33: =Table29[[#This Row],[Close Date]]-Table29[[#This Row],[Open Date]] -> 0
B34: 18 | C34: #VALUE! | D34: NASDAQ | E34: USD | F34: 331 | G34: 10 | H34: =2.02+2.05 -> 4.07 | I34: =((F34*G34)+H34)/G34 -> 331.407 | J34: =I34*G34 -> 3314.07 | K34: {=_FV(C34,"Price")} -> 282.19 | L34: =(N34-I34)*G34 -> -36.07 | M34: =L34/J34 -> -0.010883898 | N34: 327.8 | O34: 44529 | P34: 44529 | Q34: =Table29[[#This Row],[Close Date]]-Table29[[#This Row],[Open Date]] -> 0
B35: 19 | C35: #VALUE! | D35: NASDAQ | E35: USD | F35: 33.9 | G35: 100 | H35: =2.29+2.32 -> 4.61 | I35: =((F35*G35)+H35)/G35 -> 33.9461 | J35: =I35*G35 -> 3394.61 | K35: {=_FV(C35,"Price")} -> 26.48 | L35: =(N35-I35)*G35 -> 5.39 | M35: =L35/J35 -> 0.0015878113 | N35: 34 | O35: 44530 | P35: 44530 | Q35: =Table29[[#This Row],[Close Date]]-Table29[[#This Row],[Open Date]] -> 0
B36: 20 | C36: #VALUE! | D36: NYSE | E36: USD | F36: 38.8 | G36: 100 | H36: =2.32+2.29 -> 4.61 | I36: =((F36*G36)+H36)/G36 -> 38.8461 | J36: =I36*G36 -> 3884.61 | K36: {=_FV(C36,"Price")} -> 21.21 | L36: =(N36-I36)*G36 -> 15.39 | M36: =L36/J36 -> 0.0039617877 | N36: 39 | O36: 44530 | P36: 44530 | Q36: =Table29[[#This Row],[Close Date]]-Table29[[#This Row],[Open Date]] -> 0
B37: 21 | C37: #VALUE! | D37: NASDAQ | E37: USD | F37: 35.5 | G37: 120 | H37: =2.35+2.32+2.07 -> 6.74 | I37: =((F37*G37)+H37)/G37 -> 35.556167 | J37: =I37*G37 -> 4266.74 | K37: {=_FV(C37,"Price")} -> 26.48 | L37: =(N37-I37)*G37 -> 45.26 | M37: =L37/J37 -> 0.01060763 | N37: =(35.8*100+36.6*20)/120 -> 35.933333 | O37: 44531 | P37: 44531 | Q37: =Table29[[#This Row],[Close Date]]-Table29[[#This Row],[Open Date]] -> 0
B38: 22 | C38: #VALUE! | D38: NYSE | E38: USD | F38: 8.3 | G38: 400 | H38: =5.16+5.23 -> 10.39 | I38: =((F38*G38)+H38)/G38 -> 8.325975 | J38: =I38*G38 -> 3330.39 | K38: {=_FV(C38,"Price")} -> 3.02 | L38: =(N38-I38)*G38 -> 29.61 | M38: =L38/J38 -> 0.0088908506 | N38: 8.4 | O38: 44532 | P38: 44532 | Q38: =Table29[[#This Row],[Close Date]]-Table29[[#This Row],[Open Date]] -> 0
B39: 23 | C39: #VALUE! | D39: NASDAQ | E39: USD | F39: 28.9 | G39: 150 | H39: =2.14+2.48+2.29 -> 6.91 | I39: =((F39*G39)+H39)/G39 -> 28.946067 | J39: =I39*G39 -> 4341.91 | K39: {=_FV(C39,"Price")} -> 23.45 | L39: =(N39-I39)*G39 -> 12.59 | M39: =L39/J39 -> 0.0028996455 | N39: 29.03 | O39: 44532 | P39: 44532 | Q39: =Table29[[#This Row],[Close Date]]-Table29[[#This Row],[Open Date]] -> 0
B40: 24 | C40: #VALUE! | D40: NYSE | E40: USD | F40: 6.85 | G40: 670 | H40: =8.64+3.52+5.22 -> 17.38 | I40: =((F40*G40)+H40)/G40 -> 6.8759403 | J40: =I40*G40 -> 4606.88 | K40: {=_FV(C40,"Price")} -> 5.22 | L40: =(N40-I40)*G40 -> 15.72 | M40: =L40/J40 -> 0.0034122877 | N40: =(6.872*400+6.94*270)/670 -> 6.899403 | O40: 44532 | P40: 44532 | Q40: =Table29[[#This Row],[Close Date]]-Table29[[#This Row],[Open Date]] -> 0
B41: 25 | C41: #VALUE! | D41: NASDAQ | E41: USD | F41: 31.8 | G41: 100 | H41: =2.29+2.32 -> 4.61 | I41: =((F41*G41)+H41)/G41 -> 31.8461 | J41: =I41*G41 -> 3184.61 | K41: {=_FV(C41,"Price")} -> 26.48 | L41: =(N41-I41)*G41 -> 65.39 | M41: =L41/J41 -> 0.020533127 | N41: 32.5 | O41: 44533 | P41: 44533 | Q41: =Table29[[#This Row],[Close Date]]-Table29[[#This Row],[Open Date]] -> 0
B42: 26 | C42: #VALUE! | D42: NASDAQ | E42: USD | F42: 54.5 | G42: 80 | H42: =2.23+2.26 -> 4.49 | I42: =((F42*G42)+H42)/G42 -> 54.556125 | J42: =I42*G42 -> 4364.49 | K42: {=_FV(C42,"Price")} -> 43.67 | L42: =(N42-I42)*G42 -> 19.51 | M42: =L42/J42 -> 0.0044701672 | N42: 54.8 | O42: 44533 | P42: 44533 | Q42: =Table29[[#This Row],[Close Date]]-Table29[[#This Row],[Open Date]] -> 0
B43: 27 | C43: #VALUE! | D43: NYSE | E43: USD | F43: 6.1 | G43: 700 | H43: =9.13+9.03 -> 18.16 | I43: =((F43*G43)+H43)/G43 -> 6.1259429 | J43: =I43*G43 -> 4288.16 | K43: {=_FV(C43,"Price")} -> 5.22 | L43: =(N43-I43)*G43 -> 23.84 | M43: =L43/J43 -> 0.005559494 | N43: 6.16 | O43: 44533 | P43: 44533 | Q43: =Table29[[#This Row],[Close Date]]-Table29[[#This Row],[Open Date]] -> 0
B44: 28 | C44: #VALUE! | D44: NASDAQ | E44: USD | F44: =(150*30.18+28.9*8)/158 -> 30.11519 | G44: 158 | H44: =2.44+2.01+2.5 -> 6.95 | I44: =((F44*G44)+H44)/G44 -> 30.159177 | J44: =I44*G44 -> 4765.15 | K44: {=_FV(C44,"Price")} -> 26.48 | L44: =(N44-I44)*G44 -> -341.15 | M44: =L44/J44 -> -0.07159271 | N44: 28 | O44: 44533 | P44: 44536 | Q44: =Table29[[#This Row],[Close Date]]-Table29[[#This Row],[Open Date]] -> 3
B45: 29 | C45: #VALUE! | D45: NYSE | E45: USD | F45: 18.5 | G45: 200 | H45: =2.59+2.63 -> 5.22 | I45: =((F45*G45)+H45)/G45 -> 18.5261 | J45: =I45*G45 -> 3705.22 | K45: {=_FV(C45,"Price")} -> 12.31 | L45: =(N45-I45)*G45 -> 54.78 | M45: =L45/J45 -> 0.014784547 | N45: 18.8 | O45: 44536 | P45: 44536 | Q45: =Table29[[#This Row],[Close Date]]-Table29[[#This Row],[Open Date]] -> 0
B46: 30 | C46: #VALUE! | D46: NYSE | E46: USD | F46: 20 | G46: 220 | H46: =2.84+2.63+2.07+0.35 -> 7.89 | I46: =((F46*G46)+H46)/G46 -> 20.035864 | J46: =I46*G46 -> 4407.89 | K46: {=_FV(C46,"Price")} -> 12.31 | L46: =(N46-I46)*G46 -> -147.89 | M46: =L46/J46 -> -0.0335512 | N46: =(19.3*200+20*20)/220 -> 19.363636 | O46: 44536 | P46: 44537 | Q46: =Table29[[#This Row],[Close Date]]-Table29[[#This Row],[Open Date]] -> 1
...

Sheet Day Trade
C3: No. | D3: Date | E3: Stock | F3: Currency | G3: Grade | H3: Buy | I3: Quantity | J3: Fee | K3: Average Price | L3: Total Investment | M3: Sell Price | N3: Gain | O3: P % | P3: Stop Price | Q3: Loss | R3: L %
C4: 1 | D4: 01/12/2021 | E4: #VALUE! | F4: USD | G4: A | H4: 255 | I4: 100 | J4: =8.88*2+1 -> 18.76 | K4: =((H4*I4)+J4)/I4 -> 255.1876 | L4: =K4*I4 -> 25518.76 | M4: 255.37 | N4: =(M4-K4)*I4 -> 18.24 | O4: =N4/L4 -> 0.00071476827
C5: 2 | E5: #VALUE! | F5: USD | G5: A | H5: 255 | I5: 100 | J5: =8.88*2+1 -> 18.76 | K5: =((H5*I5)+J5)/I5 -> 255.1876 | L5: =K5*I5 -> 25518.76 | M5: 255.61 | N5: =(M5-K5)*I5 -> 42.24 | O5: =N5/L5 -> 0.0016552528
C6: 3 | E6: #VALUE! | F6: USD | G6: A | H6: 255.5 | I6: 100 | J6: =8.88*2+1 -> 18.76 | K6: =((H6*I6)+J6)/I6 -> 255.6876 | L6: =K6*I6 -> 25568.76 | P6: 253.11 | Q6: =(P6-K6)*I6 -> -257.76 | R6: =Q6/L6 -> -0.010081052
C7: 4 | E7: #VALUE! | F7: USD | G7: A | H7: 254 | I7: 150 | J7: =8.88*2+1 -> 18.76 | K7: =((H7*I7)+J7)/I7 -> 254.12507 | L7: =K7*I7 -> 38118.76 | P7: 251.98 | Q7: =(P7-K7)*I7 -> -321.76 | R7: =Q7/L7 -> -0.0084409881
C8: 5 | E8: #VALUE! | F8: USD | G8: C | H8: 63 | I8: 200 | J8: =8.88*4+2 -> 37.52 | K8: =((H8*I8)+J8)/I8 -> 63.1876 | L8: =K8*I8 -> 12637.52 | P8: 63 | Q8: =(P8-K8)*I8 -> -37.52 | R8: =Q8/L8 -> -0.0029689369
C9: 6 | D9: 01/13/2021 | E9: #VALUE! | F9: USD | G9: A | H9: 228.13 | I9: 150 | J9: =8.88*2+1 -> 18.76 | K9: =((H9*I9)+J9)/I9 -> 228.25507 | L9: =K9*I9 -> 34238.26 | M9: 229 | N9: =(M9-K9)*I9 -> 111.74 | O9: =N9/L9 -> 0.0032636004
C10: 7 | E10: #VALUE! | F10: USD | G10: A | H10: 227.15 | I10: 150 | J10: =8.88*2+1 -> 18.76 | K10: =((H10*I10)+J10)/I10 -> 227.27507 | L10: =K10*I10 -> 34091.26 | M10: 227.59 | N10: =(M10-K10)*I10 -> 47.24 | O10: =N10/L10 -> 0.0013856924
C11: 8 | E11: #VALUE! | F11: USD | G11: A | H11: 227.95 | I11: 150 | J11: =8.88*2+1 -> 18.76 | K11: =((H11*I11)+J11)/I11 -> 228.07507 | L11: =K11*I11 -> 34211.26 | M11: 228.66 | N11: =(M11-K11)*I11 -> 87.74 | O11: =N11/L11 -> 0.0025646527
C12: 9 | E12: #VALUE! | F12: USD | G12: A | H12: 228.45 | I12: 150 | J12: =8.88*2+1 -> 18.76 | K12: =((H12*I12)+J12)/I12 -> 228.57507 | L12: =K12*I12 -> 34286.26 | M12: 228.6 | N12: =(M12-K12)*I12 -> 3.74 | O12: =N12/L12 -> 0.0001090816
C13: 10 | D13: 01/14/2021 | E13: #VALUE! | F13: HKD | G13: A | H13: 234.2 | I13: 1500 | J13: =(H13*I13+M13*I13)*0.12%+(H13*I13+M13*I13)*(0.1%+0.002%+0.0027%+0.005%) -> 806.9361 | K13: =((H13*I13)+J13)/I13 -> 234.73796 | L13: =K13*I13 -> 352106.94 | P13: 234.6 | Q13: =(P13-K13)*I13 -> -206.9361 | R13: =Q13/L13 -> -0.0005877081
C14: 11 | E14: #VALUE! | F14: USD | G14: A | H14: 243.81 | I14: 150 | J14: =8.88*2+1 -> 18.76 | K14: =((H14*I14)+J14)/I14 -> 243.93507 | L14: =K14*I14 -> 36590.26 | M14: 244 | N14: =(M14-K14)*I14 -> 9.74 | O14: =N14/L14 -> 0.00026619106
C15: 12 | E15: #VALUE! | F15: USD | G15: A | H15: 242 | I15: 50 | J15: =8.88*2+1 -> 18.76 | K15: =((H15*I15)+J15)/I15 -> 242.3752 | L15: =K15*I15 -> 12118.76 | M15: 244 | N15: =(M15-K15)*I15 -> 81.24 | O15: =N15/L15 -> 0.0067036561
C16: 13 | D16: 01/15/2021 | E16: #VALUE! | F16: HKD | G16: A | H16: 242.8 | I16: 1000 | J16: =(H16*I16+P16*I16)*0.12%+(H16*I16+P16*I16)*(0.1%+0.002%+0.0027%+0.005%) -> 1108.9916 | K16: =((H16*I16)+J16)/I16 -> 243.90899 | L16: =K16*I16 -> 243908.99 | P16: 240 | Q16: =(P16-K16)*I16/7.8 -> -501.15277 | R16: =Q16/L16 -> -0.0020546712
C17: 14 | E17: #VALUE! | F17: HKD | G17: A | H17: 240 | I17: 600 | J17: =(H17*I17+P17*I17)*0.12%+(H17*I17+P17*I17)*(0.1%+0.002%+0.0027%+0.005%) -> 662.63856 | K17: =((H17*I17)+J17)/I17 -> 241.1044 | L17: =K17*I17 -> 144662.64 | P17: 240.8 | Q17: =(P17-K17)*I17/7.8 -> -23.4152 | R17: =Q17/L17 -> -0.00016186073
C18: 15 | E18: #VALUE! | F18: HKD | G18: A | H18: 239.8 | I18: 500 | J18: =(H18*I18+P18*I18)*0.12%+(H18*I18+P18*I18)*(0.1%+0.002%+0.0027%+0.005%) -> 551.9691 | K18: =((H18*I18)+J18)/I18 -> 240.90394 | L18: =K18*I18 -> 120451.97 | P18: 240.8 | Q18: =(P18-K18)*I18/7.8 -> -6.6627051 | R18: =Q18/L18 -> -5.5314207e-05
C19: 16 | E19: #VALUE! | F19: USD | G19: A | H19: 243.9 | I19: 100 | J19: =8.88*2+1 -> 18.76 | K19: =((H19*I19)+J19)/I19 -> 244.0876 | L19: =K19*I19 -> 24408.76 | M19: 244.21 | N19: =(M19-K19)*I19 -> 12.24 | O19: =N19/L19 -> 0.00050145931
C20: 17 | E20: #VALUE! | F20: USD | G20: B | H20: 391.15 | I20: 60 | J20: =8.88*2+1 -> 18.76 | K20: =((H20*I20)+J20)/I20 -> 391.46267 | L20: =K20*I20 -> 23487.76 | M20: 391.58 | N20: =(M20-K20)*I20 -> 7.04 | O20: =N20/L20 -> 0.00029973058
C21: 18 | E21: #VALUE! | F21: USD | G21: A | H21: 243.02 | I21: 100 | J21: =8.88*2+1 -> 18.76 | K21: =((H21*I21)+J21)/I21 -> 243.2076 | L21: =K21*I21 -> 24320.76 | M21: 243.72 | N21: =(M21-K21)*I21 -> 51.24 | O21: =N21/L21 -> 0.0021068421
C22: 19 | E22: #VALUE! | F22: USD | G22: B | H22: 394.1 | I22: 60 | J22: =8.88*2+1 -> 18.76 | K22: =((H22*I22)+J22)/I22 -> 394.41267 | L22: =K22*I22 -> 23664.76 | P22: 383.03 | Q22: =(P22-K22)*I22 -> -682.96 | R22: =Q22/L22 -> -0.02885979
C23: 20 | E23: #VALUE! | F23: USD | G23: B | H23: 390.9 | I23: 60 | J23: =8.88*2+1 -> 18.76 | K23: =((H23*I23)+J23)/I23 -> 391.21267 | L23: =K23*I23 -> 23472.76 | P23: 383.03 | Q23: =(P23-K23)*I23 -> -490.96 | R23: =Q23/L23 -> -0.02091616
C24: 21 | E24: #VALUE! | F24: USD | G24: B | H24: 385.55 | I24: 70 | J24: =8.88*2+1 -> 18.76 | K24: =((H24*I24)+J24)/I24 -> 385.818 | L24: =K24*I24 -> 27007.26 | M24: 386 | N24: =(M24-K24)*I24 -> 12.74 | O24: =N24/L24 -> 0.00047172501
C25: 22 | D25: 01/18/2021 | E25: #VALUE! | F25: HKD | G25: A | H25: 241.8 | I25: 800 | J25: =(H25*I25+P25*I25)*0.12%+(H25*I25+P25*I25)*(0.1%+0.002%+0.0027%+0.005%) -> 889.3984 | K25: =((H25*I25)+J25)/I25 -> 242.91175 | L25: =K25*I25 -> 194329.4 | P25: 242.2 | Q25: =(P25-K25)*I25/7.8 -> -72.999795 | R25: =Q25/L25 -> -0.00037564978
C26: 23 | E26: #VALUE! | F26: HKD | G26: A | H26: 240.4 | I26: 900 | J26: =(H26*I26+M26*I26)*0.12%+(H26*I26+M26*I26)*(0.1%+0.002%+0.0027%+0.005%) -> 997.67898 | K26: =((H26*I26)+J26)/I26 -> 241.50853 | L26: =K26*I26 -> 217357.68 | M26: 242.2 | N26: =(M26-K26)*I26/7.8 -> 79.784746 | O26: =N26/L26 -> 0.00036706661
C27: 24 | D27: 01/19/2021 | E27: #VALUE! | F27: HKD | G27: A | H27: 243.4 | I27: 800 | J27: =(H27*I27+P27*I27)*0.12%+(H27*I27+P27*I27)*(0.1%+0.002%+0.0027%+0.005%) -> 896.01376 | K27: =((H27*I27)+J27)/I27 -> 244.52002 | L27: =K27*I27 -> 195616.01 | P27: 244.2 | Q27: =(P27-K27)*I27/7.8 -> -32.822277 | R27: =Q27/L27 -> -0.00016778931
C28: 25 | E28: #VALUE! | F28: USD | G28: C | H28: 57 | I28: 100 | J28: =8.88*2+1 -> 18.76 | K28: =((H28*I28)+J28)/I28 -> 57.1876 | L28: =K28*I28 -> 5718.76 | M28: 58.2 | N28: =(M28-K28)*I28 -> 101.24 | O28: =N28/L28 -> 0.017703138
C29: 26 | D29: 01/20/2021 | E29: #VALUE! | F29: USD | G29: A | H29: 265 | I29: 100 | J29: =8.88*2+1 -> 18.76 | K29: =((H29*I29)+J29)/I29 -> 265.1876 | L29: =K29*I29 -> 26518.76 | M29: 266.2 | N29: =(M29-K29)*I29 -> 101.24 | O29: =N29/L29 -> 0.0038176747
C30: 27 | E30: #VALUE! | F30: USD | G30: C | H30: 58 | I30: 100 | J30: =8.88*2+1 -> 18.76 | K30: =((H30*I30)+J30)/I30 -> 58.1876 | L30: =K30*I30 -> 5818.76 | P30: 58 | Q30: =(P30-K30)*I30 -> -18.76 | R30: =Q30/L30 -> -0.0032240546
C31: 28 | E31: #VALUE! | F31: USD | G31: A | H31: 267.5 | I31: 80 | J31: =8.88*2+1 -> 18.76 | K31: =((H31*I31)+J31)/I31 -> 267.7345 | L31: =K31*I31 -> 21418.76 | M31: 268 | N31: =(M31-K31)*I31 -> 21.24 | O31: =N31/L31 -> 0.00099165405
C32: 29 | E32: #VALUE! | F32: USD | G32: A | H32: 267 | I32: 100 | J32: =8.88*2+1 -> 18.76 | K32: =((H32*I32)+J32)/I32 -> 267.1876 | L32: =K32*I32 -> 26718.76 | M32: 268 | N32: =(M32-K32)*I32 -> 81.24 | O32: =N32/L32 -> 0.0030405603
C33: 30 | D33: 01/21/2021 | E33: #VALUE! | F33: USD | G33: A | H33: 271.5 | I33: 100 | J33: =8.88*2+1 -> 18.76 | K33: =((H33*I33)+J33)/I33 -> 271.6876 | L33: =K33*I33 -> 27168.76 | M33: 273 | N33: =(M33-K33)*I33 -> 131.24 | O33: =N33/L33 -> 0.004830548
C34: 31 | E34: #VALUE! | F34: USD | G34: A | H34: 259.5 | I34: 100 | J34: =8.88*2+1 -> 18.76 | K34: =((H34*I34)+J34)/I34 -> 259.6876 | L34: =K34*I34 -> 25968.76 | M34: 260 | N34: =(M34-K34)*I34 -> 31.24 | O34: =N34/L34 -> 0.0012029839
C35: 32 | D35: 01/22/2021 | E35: #VALUE! | F35: USD | G35: C | H35: 59.19 | I35: 50 | J35: =8.88*2+1 -> 18.76 | K35: =((H35*I35)+J35)/I35 -> 59.5652 | L35: =K35*I35 -> 2978.26 | M35: 61 | N35: =(M35-K35)*I35 -> 71.74 | O35: =N35/L35 -> 0.02408789
C36: 33 | E36: #VALUE! | F36: USD | G36: C | H36: 59.19 | I36: 50 | J36: =8.88+1 -> 9.88 | K36: =((H36*I36)+J36)/I36 -> 59.3876 | L36: =K36*I36 -> 2969.38 | M36: 61.25 | N36: =(M36-K36)*I36 -> 93.12 | O36: =N36/L36 -> 0.031360082
C37: 34 | E37: #VALUE! | F37: USD | G37: A | H37: 276 | I37: 100 | J37: =8.88*2+1 -> 18.76 | K37: =((H37*I37)+J37)/I37 -> 276.1876 | L37: =K37*I37 -> 27618.76 | M37: 277 | N37: =(M37-K37)*I37 -> 81.24 | O37: =N37/L37 -> 0.0029414789
C38: 35 | E38: #VALUE! | F38: USD | G38: C | H38: 61.5 | I38: 100 | J38: =8.88*2+1 -> 18.76 | K38: =((H38*I38)+J38)/I38 -> 61.6876 | L38: =K38*I38 -> 6168.76 | P38: 61 | Q38: =(P38-K38)*I38 -> -68.76 | R38: =Q38/L38 -> -0.011146486
C39: 36 | D39: 01/25/2021 | E39: #VALUE! | F39: USD | G39: A | H39: =(276.5+274.8)/2 -> 275.65 | I39: 200 | J39: =8.88*3+1 -> 27.64 | K39: =((H39*I39)+J39)/I39 -> 275.7882 | L39: =K39*I39 -> 55157.64 | P39: 273 | Q39: =(P39-K39)*I39 -> -557.64 | R39: =Q39/L39 -> -0.010109932
C40: 37 | E40: #VALUE! | F40: USD | G40: A | H40: =(274.5+274)/2 -> 274.25 | I40: 200 | J40: =8.88*3+1 -> 27.64 | K40: =((H40*I40)+J40)/I40 -> 274.3882 | L40: =K40*I40 -> 54877.64 | M40: 274.53 | N40: =(M40-K40)*I40 -> 28.36 | O40: =N40/L40 -> 0.00051678607
C41: 38 | E41: #VALUE! | F41: USD | G41: C | H41: 59.9 | I41: 300 | J41: =8.88*3+1 -> 27.64 | K41: =((H41*I41)+J41)/I41 -> 59.992133 | L41: =K41*I41 -> 17997.64 | P41: =(59.6+60)/2 -> 59.8 | Q41: =(P41-K41)*I41 -> -57.64 | R41: =Q41/L41 -> -0.0032026421
C42: 39 | E42: #VALUE! | F42: USD | G42: A | H42: 260 | I42: 100 | J42: =8.88*2+1 -> 18.76 | K42: =((H42*I42)+J42)/I42 -> 260.1876 | L42: =K42*I42 -> 26018.76 | M42: 260.5 | N42: =(M42-K42)*I42 -> 31.24 | O42: =N42/L42 -> 0.0012006721
...

Sheet Fee and Margin
C2: Forex SGD to USD | D2: 0.75
C4: Cash Balance | D4: ='SG Portfolio'!D11 -> -33411.634 | E4: USD | I4: 0.07 | J4: Margin Interest Rate
C5: Equity Balance | D5: =D4+D10 -> 25005.558 | E5: USD | I5: =IF(D4<0,-D4*I4/360,0) -> 6.4967067 | J5: Daily Interest
C6: Margin Call | D6: =(D11*F25+D12*F26+D13*F27)-D5 -> -7864.1984 | E6: USD
C7: Force Selling | D7: =(D11*G25+D12*G26+D13*G27)-D5 -> -11302.662 | E7: USD
C9: Investment Portfolio | D9: Market Value | E9: Initial Margin | F9: Cash Equivalent | J9: Brokerage Fee | K9: Foreign Exchange Fee
D10: =SUM(D11:D13) -> 58417.192 | E10: =SUM(E11:E13) -> 20088.375 | F10: =D10-E10 -> 38328.817 | I10: HKEx | J10: 0.0006 | K10: =0.1%+0.002%+0.0027%+0.005% -> 0.001097
C11: Grade A | D11: ='SG Portfolio'!E17+'SG Portfolio'!H17 -> 42558.192 | E11: =D11*E25 -> 12158.875 | F11: =D11-E11 -> 30399.317 | I11: US | J11: 2.88 | K11: 2.21e-05
C12: Grade B | D12: ='SG Portfolio'!E18+'SG Portfolio'!H18 -> 15859 | E12: =D12*E26 -> 7929.5 | F12: =D12-E12 -> 7929.5
C13: Grade C | D13: ='SG Portfolio'!E19+'SG Portfolio'!H19 -> 0 | E13: =D13*E27 -> 0 | F13: =D13-E13 -> 0
C16: Initial Credit | D16: 150000 | E16: SGD USD | F16: =D16*D2 -> 112500
C17: Tradable Balance | D17: =D4+F10 -> 4917.1822 | E17: USD SGD | F17: =D17/D2 -> 6556.2429
D18: Buy A | E18: Buy B | F18: Buy C
C19: USD | D19: =D20*D2 -> 17210.138 | E19: =D17*L24 -> 9834.3644 | F19: =D17*M24 -> 4917.1822
C20: SGD | D20: =IF(D17*K24>(D4/D2+D16),(D4/D2+D16),D17/D2*K24) -> 22946.85 | E20: =E19/$D$2 -> 13112.486 | F20: =F19/$D$2 -> 6556.2429
C23: Grade of Investment | D23: Financing Quantum | E23: Margin Factor | J23: Purchase Deposit | K23: Grade A | L23: Grade B | M23: Grade C
E24: IM Factor | F24: MM Factor | G24: FM Factor | J24: Cash | K24: 3.5 | L24: 2 | M24: 1
C25: A | D25: 0.7 | E25: 0.2857 | F25: 0.2308 | G25: 0.1667 | J25: Grade A | K25: 2.5 | L25: 1.428 | M25: 0.714
C26: B | D26: 0.5 | E26: 0.5 | F26: 0.4615 | G26: 0.4167 | J26: Grade B | K26: 1.75 | L26: 1 | M26: 0.5
C27: C | D27: 0 | E27: 1 | F27: 1 | G27: 1 | J27: Grade C | K27: 0 | L27: 0 | M27: 0
C30: Strategy
F31: Buy A | G31: Buy B | H31: Buy C
C32: F | D32: 下注比率 | E32: =(E34*E33-E35)/E33 -> 0.3037037 | F32: =$E$32*D19 -> 5226.7826 | G32: =$E$32*E19 -> 2986.7329 | H32: =$E$32*F19 -> 1493.3664
C33: B | D33: 赔率 | E33: 1.35
C34: P | D34: 估算胜率 | E34: 0.6
C35: Q | D35: 失败概率 | E35: =1-E34 -> 0.4
C36: G | D36: 目标 (止盈) | E36: 100 | F36: =$E$36/F32 -> 0.019132229 | G36: =$E$36/G32 -> 0.0334814 | H36: =$E$36/H32 -> 0.066962801
C37: L | D37: 目标 (止损) | E37: =E36/E33 -> 74.074074 | F37: =-$E$37/F32 -> -0.014172021 | G37: =-$E$37/G32 -> -0.024801037 | H37: =-$E$37/H32 -> -0.049602075
C40: 胜率估算
D41: 基本胜率 | E41: 0.5
D42: 最高增率 | E42: 0.1
C44: 比重 | D44: 涨跌 | E44: -0.03 | F44: -0.02 | G44: -0.01 | H44: 0 | I44: 0.01 | J44: 0.02 | K44: 0.03
C45: 0.3 | D45: 大盘 | E45: -1 | F45: -0.75 | G45: 0.5 | H45: 0.25 | I45: 0.5 | J45: 0.75 | K45: 1
E46: =$E$42*$C$45*E45 -> -0.03 | F46: =$E$42*$C$45*F45 -> -0.0225 | G46: =$E$42*$C$45*G45 -> 0.015 | H46: =$E$42*$C$45*H45 -> 0.0075 | I46: =$E$42*$C$45*I45 -> 0.015 | J46: =$E$42*$C$45*J45 -> 0.0225 | K46: =$E$42*$C$45*K45 -> 0.03
C47: 0.4 | D47: 个股 | E47: 1 | F47: 0.5 | G47: 0.25 | H47: 0 | I47: 0.25 | J47: 1 | K47: 0.75
E48: =$E$42*$C$47*E47 -> 0.04 | F48: =$E$42*$C$47*F47 -> 0.02 | G48: =$E$42*$C$47*G47 -> 0.01 | H48: =$E$42*$C$47*H47 -> 0 | I48: =$E$42*$C$47*I47 -> 0.01 | J48: =$E$42*$C$47*J47 -> 0.04 | K48: =$E$42*$C$47*K47 -> 0.03
C49: 0.3 | D49: 个股振幅 | E49: 0.01 | F49: 0.02 | G49: 0.03 | H49: 0.04 | I49: 0.05 | J49: 0.06 | K49: 0.07
E50: 0 | F50: 0.5 | G50: 1 | H50: 0.75 | I50: 0.5 | J50: 0.25 | K50: 0
E51: =$E$42*$C$49*E50 -> 0 | F51: =$E$42*$C$49*F50 -> 0.015 | G51: =$E$42*$C$49*G50 -> 0.03 | H51: =$E$42*$C$49*H50 -> 0.0225 | I51: =$E$42*$C$49*I50 -> 0.015 | J51: =$E$42*$C$49*J50 -> 0.0075 | K51: =$E$42*$C$49*K50 -> 0

Sheet IndoStock
E1: Return | F1: Realized Gain
B2: Cash in | C2: 25000000 | E2: =F2/C2 -> -0.0094 | F2: =K11 -> -235000
B3: Investment | C3: =I8+I9 -> 4815000 | D3: =C3/C2 -> 0.1926
B4: Balance | C4: =C2-C3 -> 20185000 | D4: =C4/C2 -> 0.8074
B7: Stock Name | C7: Market | D7: Currency | E7: Buy Price | F7: Quantity | G7: Fee | H7: Average Price | I7: Total | J7: Current Price | K7: Gain/Loss | M7: Date
B8: #VALUE! | C8: IDX | D8: IDR | E8: 4560 | F8: =5*100 -> 500 | G8: =25000*2 -> 50000 | H8: =((E8*F8)+G8)/F8 -> 4660 | I8: =H8*F8 -> 2330000 | J8: 4550 | K8: =(J8-H8)*F8 -> -55000 | L8: =K8/I8 -> -0.02360515 | M8: 44014 | N8: Open
B9: #VALUE! | C9: IDX | D9: IDR | E9: 4870 | F9: =5*100 -> 500 | G9: =25000*2 -> 50000 | H9: =((E9*F9)+G9)/F9 -> 4970 | I9: =H9*F9 -> 2485000 | J9: 4610 | K9: =(J9-H9)*F9 -> -180000 | L9: =K9/I9 -> -0.072434608 | M9: 44014 | N9: Open
G11: =SUM(G8:G10) -> 100000 | K11: =SUM(K8:K10) -> -235000
B15: #VALUE! | C15: IDX | D15: IDR | E15: =E8 -> 4560 | F15: =F8 -> 500 | G15: =G8 -> 50000 | H15: =((E15*F15)+G15)/F15 -> 4660 | I15: =H15*F15 -> 2330000 | J15: 4560 | K15: =(J15-H15)*F15 -> -50000 | L15: =K15/I15 -> -0.021459227 | M15: 1st
B16: =E16/E15 -> 0.8004386 | C16: IDX | D16: IDR | E16: 3650 | F16: 800 | G16: =G15 -> 50000 | H16: =((E16*F16)+G16)/F16 -> 3712.5 | I16: =H16*F16 -> 2970000 | M16: 2nd
B17: =E17/E16 -> 0.79452055 | C17: IDX | D17: IDR | E17: 2900 | F17: =F16*2 -> 1600 | G17: =G16 -> 50000 | H17: =((E17*F17)+G17)/F17 -> 2931.25 | I17: =H17*F17 -> 4690000 | M17: 3rd
C18: IDX | D18: IDR | E18: =(E15*F15+E16*F16+E17*F17)/SUM(F15:F17) -> 3393.1034 | F18: =SUM(F15:F17) -> 2900 | G18: =SUM(G15:G17) -> 150000 | H18: =((E18*F18)+G18)/F18 -> 3444.8276 | I18: =H18*F18 -> 9990000 | J18: =E17 -> 2900 | K18: =(J18-H18)*F18 -> -1580000 | L18: =K18/I18 -> -0.15815816 | M18: Total
B21: #VALUE! | C21: IDX | D21: IDR | E21: =E9 -> 4870 | F21: =F9 -> 500 | G21: =G9 -> 50000 | H21: =((E21*F21)+G21)/F21 -> 4970 | I21: =H21*F21 -> 2485000 | J21: =J9 -> 4610 | K21: =(J21-H21)*F21 -> -180000 | L21: =K21/I21 -> -0.072434608 | M21: 1st
B22: =E22/E21 -> 0.80082136 | C22: IDX | D22: IDR | E22: 3900 | F22: 800 | G22: =G21 -> 50000 | H22: =((E22*F22)+G22)/F22 -> 3962.5 | I22: =H22*F22 -> 3170000 | M22: 2nd
B23: =E23/E22 -> 0.79487179 | C23: IDX | D23: IDR | E23: 3100 | F23: =F22*2 -> 1600 | G23: =G22 -> 50000 | H23: =((E23*F23)+G23)/F23 -> 3131.25 | I23: =H23*F23 -> 5010000 | M23: 3rd
C24: IDX | D24: IDR | E24: =(E21*F21+E22*F22+E23*F23)/SUM(F21:F23) -> 3625.8621 | F24: =SUM(F21:F23) -> 2900 | G24: =SUM(G21:G23) -> 150000 | H24: =((E24*F24)+G24)/F24 -> 3677.5862 | I24: =H24*F24 -> 10665000 | J24: =E23 -> 3100 | K24: =(J24-H24)*F24 -> -1675000 | L24: =K24/I24 -> -0.15705579 | M24: Total
B27: Worst | C27: Total Investment | E27: =SUM(E28:E29) -> 20655000 | F27: =E27/$C$2 -> 0.8262
B28: Scenario | C28: 1 | D28: =B15 -> #VALUE! | E28: =I18 -> 9990000 | F28: =E28/$E$27 -> 0.48366013
C29: 2 | D29: =B21 -> #VALUE! | E29: =I24 -> 10665000 | F29: =E29/$E$27 -> 0.51633987
C31: P/L | E31: =K18+K24 -> -3255000 | F31: =E31/E27 -> -0.15758896
C33: Cash Balance | E33: =C2-E27 -> 4345000 | F33: =E33/$C$2 -> 0.1738

Sheet US Index Contents
E3: S&P 500 | F3: Nasdaq | G3: DJI
D4: Information technology | E4: 0.276 | F4: 0.4839 | G4: 0.1756
D5: Health care | E5: 0.1344 | F5: 0.1021 | G5: 0.1
D6: Consumer discretionary | E6: 0.127 | F6: 0.1943 | G6: 0.1449
D7: Communication services | E7: 0.1079 | F7: 0.0072 | G7: 0.05
D8: Financials | E8: 0.1034 | F8: 0.0721 | G8: 0.05
D9: Industrials | E9: 0.0847 | F9: 0.0685 | G9: 0.2219
D10: Consumer staples | E10: 0.0655 | F10: 0.0551 | G10: 0.1025
D11: Utilities | E11: 0.0273 | F11: 0.0081 | G11: 0.01
D12: Materials | E12: 0.0264 | F12: 0.0032 | G12: 0.0091
D13: Real estate | E13: 0.0241 | G13: 0.0217
D14: Energy | E14: 0.0233 | F14: 0.0055 | G14: 0.1143
E15: =SUM(E4:E14) -> 1 | F15: =SUM(F4:F14) -> 1 | G15: =SUM(G4:G14) -> 1

Sheet Lost Return Ratio
C5: Lost | E5: Return | G5: Ratio
C6: 0.05 | E6: 0.053 | G6: =E6/C6 -> 1.06
C7: 0.1 | E7: 0.11 | G7: =E7/C7 -> 1.1
C8: 0.15 | E8: 0.18 | G8: =E8/C8 -> 1.2
C9: 0.2 | E9: 0.25 | G9: =E9/C9 -> 1.25
C10: 0.25 | E10: 0.33 | G10: =E10/C10 -> 1.32
C11: 0.3 | E11: 0.43 | G11: =E11/C11 -> 1.4333333
C12: 0.4 | E12: 0.67 | G12: =E12/C12 -> 1.675
C13: 0.5 | E13: 1 | G13: =E13/C13 -> 2

Sheet SG Watchlist
D3: No. | E3: Stock Name | F3: Price | G3: 52 wks high | H3: 52 wks low | I3: PE | J3: PB | K3: MA5 | L3: MA10 | M3: MA30 | N3: MA60 | O3: Good Price | P3: L/R Trade
D5: 1 | E5: #VALUE! | F5: {=_FV(E5,"Price")} -> 310.7 | G5: {=_FV(E5,"52 week high",TRUE)} -> 349.67 | H5: {=_FV(E5,"52 week low",TRUE)} -> 231.1 | I5: {=_FV(E5,"P/E",TRUE)} -> 33.0562 | K5: 230.38 | L5: 231.16 | M5: 236.92 | N5: 228.14 | O5: =IF(AND(F5<K5,F5<L5,F5<M5,F5<N5),"Yes","No") -> No
D6: 2 | E6: #VALUE! | F6: {=_FV(E6,"Price")} -> 223.59 | G6: {=_FV(E6,"52 week high",TRUE)} -> 384.33 | H6: {=_FV(E6,"52 week low",TRUE)} -> 185.82 | I6: {=_FV(E6,"P/E",TRUE)} -> 16.2107 | K6: 261.57 | L6: 259.95 | M6: 264.76 | N6: 266.65 | O6: =IF(AND(F6<K6,F6<L6,F6<M6,F6<N6),"Yes","No") -> Yes
D7: 3 | E7: #VALUE! | F7: {=_FV(E7,"Price")} -> 378.51 | G7: {=_FV(E7,"52 week high",TRUE)} -> 700.9894 | H7: {=_FV(E7,"52 week low",TRUE)} -> 329.82 | I7: {=_FV(E7,"P/E",TRUE)} -> 35.449 | K7: 506.39 | L7: 523.67 | M7: 539.18 | N7: 532.14 | O7: =IF(AND(F7<K7,F7<L7,F7<M7,F7<N7),"Yes","No") -> Yes
D8: 4 | E8: #VALUE! | F8: {=_FV(E8,"Price")} -> 175.6 | G8: {=_FV(E8,"52 week high",TRUE)} -> 182.94 | H8: {=_FV(E8,"52 week low",TRUE)} -> 118.86 | I8: {=_FV(E8,"P/E",TRUE)} -> 28.2588 | K8: 119.79 | L8: 121.61 | M8: 129.42 | N8: 130.16 | O8: =IF(AND(F8<K8,F8<L8,F8<M8,F8<N8),"Yes","No") -> No
D9: 5 | E9: #VALUE! | F9: {=_FV(E9,"Price")} -> 450.01 | G9: {=_FV(E9,"52 week high",TRUE)} -> 699.54 | H9: {=_FV(E9,"52 week low",TRUE)} -> 407.94 | I9: {=_FV(E9,"P/E",TRUE)} -> 44.6944 | K9: 435.45 | L9: 448.07 | M9: 471.11 | N9: 477.07 | O9: =IF(AND(F9<K9,F9<L9,F9<M9,F9<N9),"Yes","No") -> No
O10: =IF(AND(F10<K10,F10<L10,F10<M10,F10<N10),"Yes","No") -> No
D11: 6 | E11: #VALUE! | F11: {=_FV(E11,"Price")} -> 1091.84 | G11: {=_FV(E11,"52 week high",TRUE)} -> 1243.49 | H11: {=_FV(E11,"52 week low",TRUE)} -> 546.98 | I11: {=_FV(E11,"P/E",TRUE)} -> 221.8457 | K11: 624.8 | L11: 653.98 | M11: 758.87 | N11: 753.41 | O11: =IF(AND(F11<K11,F11<L11,F11<M11,F11<N11),"Yes","No") -> No
D12: 7 | E12: #VALUE! | F12: {=_FV(E12,"Price")} -> 282.19 | G12: {=_FV(E12,"52 week high",TRUE)} -> 346.47 | H12: {=_FV(E12,"52 week low",TRUE)} -> 127 | I12: {=_FV(E12,"P/E",TRUE)} -> 73.3655 | K12: 491.2 | L12: 513.8 | M12: 548.7 | N12: 539.41 | O12: =IF(AND(F12<K12,F12<L12,F12<M12,F12<N12),"Yes","No") -> Yes
D13: 8 | E13: #VALUE! | F13: {=_FV(E13,"Price")} -> 120.24 | G13: {=_FV(E13,"52 week high",TRUE)} -> 164.4599 | H13: {=_FV(E13,"52 week low",TRUE)} -> 72.5 | I13: {=_FV(E13,"P/E",TRUE)} -> 46.714 | K13: 77.25 | L13: 80.45 | M13: 86.15 | N13: 89.56 | O13: =IF(AND(F13<K13,F13<L13,F13<M13,F13<N13),"Yes","No") -> No
D14: 9 | E14: #VALUE! | F14: {=_FV(E14,"Price")} -> 158.45 | G14: {=_FV(E14,"52 week high",TRUE)} -> 193.58 | H14: {=_FV(E14,"52 week low",TRUE)} -> 122.165 | I14: {=_FV(E14,"P/E",TRUE)} -> 18.1595 | O14: =IF(AND(F14<K14,F14<L14,F14<M14,F14<N14),"Yes","No") -> No
D15: 10 | E15: #VALUE! | F15: {=_FV(E15,"Price")} -> 106.33 | G15: {=_FV(E15,"52 week high",TRUE)} -> 145 | H15: {=_FV(E15,"52 week low",TRUE)} -> 97.62 | I15: {=_FV(E15,"P/E",TRUE)} -> 25.6167 | O15: =IF(AND(F15<K15,F15<L15,F15<M15,F15<N15),"Yes","No") -> No
D16: 11 | E16: #VALUE! | F16: {=_FV(E16,"Price")} -> 79.86 | G16: {=_FV(E16,"52 week high",TRUE)} -> 98.45 | H16: {=_FV(E16,"52 week low",TRUE)} -> 65.67 | I16: {=_FV(E16,"P/E",TRUE)} -> 12.1791 | O16: =IF(AND(F16<K16,F16<L16,F16<M16,F16<N16),"Yes","No") -> No
D17: 12 | E17: #VALUE! | F17: {=_FV(E17,"Price")} -> 694.83 | G17: {=_FV(E17,"52 week high",TRUE)} -> 895.93 | H17: {=_FV(E17,"52 week low",TRUE)} -> 558.77 | I17: {=_FV(E17,"P/E",TRUE)} -> 42.5649 | O17: =IF(AND(F17<K17,F17<L17,F17<M17,F17<N17),"Yes","No") -> No
D18: 13 | E18: #VALUE! | F18: {=_FV(E18,"Price")} -> 51.51 | G18: {=_FV(E18,"52 week high",TRUE)} -> 68.49 | H18: {=_FV(E18,"52 week low",TRUE)} -> 43.625 | I18: {=_FV(E18,"P/E",TRUE)} -> 10.6038 | K18: 60.76 | L18: 60.9 | M18: 59.82 | N18: 55.78 | O18: =IF(AND(F18<K18,F18<L18,F18<M18,F18<N18),"Yes","No") -> Yes
D19: 14 | E19: #VALUE! | F19: {=_FV(E19,"Price")} -> 69.82 | G19: {=_FV(E19,"52 week high",TRUE)} -> 194.99 | H19: {=_FV(E19,"52 week low",TRUE)} -> 50.08 | I19: {=_FV(E19,"P/E",TRUE)} -> 0 | O19: =IF(AND(F19<K19,F19<L19,F19<M19,F19<N19),"Yes","No") -> No
D21: 15 | E21: #VALUE! | F21: {=_FV(E21,"Price")} -> 21.25 | G21: {=_FV(E21,"52 week high",TRUE)} -> 72.2 | H21: {=_FV(E21,"52 week low",TRUE)} -> 17.27 | I21: {=_FV(E21,"P/E",TRUE)} -> #VALUE! | O21: =IF(AND(F21<K21,F21<L21,F21<M21,F21<N21),"Yes","No") -> No
D22: 16 | E22: #VALUE! | F22: {=_FV(E22,"Price")} -> 17.33 | G22: {=_FV(E22,"52 week high",TRUE)} -> 75.15 | H22: {=_FV(E22,"52 week low",TRUE)} -> 13.01 | I22: {=_FV(E22,"P/E",TRUE)} -> 0 | O22: =IF(AND(F22<K22,F22<L22,F22<M22,F22<N22),"Yes","No") -> No
D23: 17 | E23: #VALUE! | F23: {=_FV(E23,"Price")} -> 39.12 | G23: {=_FV(E23,"52 week high",TRUE)} -> 73.34 | H23: {=_FV(E23,"52 week low",TRUE)} -> 31.3 | I23: {=_FV(E23,"P/E",TRUE)} -> 0 | O23: =IF(AND(F23<K23,F23<L23,F23<M23,F23<N23),"Yes","No") -> No
D24: 18 | E24: #VALUE! | F24: {=_FV(E24,"Price")} -> 37.59 | G24: {=_FV(E24,"52 week high",TRUE)} -> 65.94 | H24: {=_FV(E24,"52 week low",TRUE)} -> 33.94 | I24: {=_FV(E24,"P/E",TRUE)} -> #VALUE! | O24: =IF(AND(F24<K24,F24<L24,F24<M24,F24<N24),"Yes","No") -> No
D25: 19 | E25: #VALUE! | F25: {=_FV(E25,"Price")} -> 34.77 | G25: {=_FV(E25,"52 week high",TRUE)} -> 61.5 | H25: {=_FV(E25,"52 week low",TRUE)} -> 28.2777 | I25: {=_FV(E25,"P/E",TRUE)} -> 0 | O25: =IF(AND(F25<K25,F25<L25,F25<M25,F25<N25),"Yes","No") -> No
D27: 20 | E27: #VALUE! | F27: {=_FV(E27,"Price")} -> 138.72 | G27: {=_FV(E27,"52 week high",TRUE)} -> 191.67 | H27: {=_FV(E27,"52 week low",TRUE)} -> 128.38 | I27: {=_FV(E27,"P/E",TRUE)} -> 80.624 | O27: =IF(AND(F27<K27,F27<L27,F27<M27,F27<N27),"Yes","No") -> No
D28: 21 | E28: #VALUE! | F28: {=_FV(E28,"Price")} -> 128.04 | G28: {=_FV(E28,"52 week high",TRUE)} -> 148.93 | H28: {=_FV(E28,"52 week low",TRUE)} -> 117.58 | I28: {=_FV(E28,"P/E",TRUE)} -> 57.6207 | K28: 130.58 | L28: 132.49 | M28: 139.75 | N28: 140.55 | O28: =IF(AND(F28<K28,F28<L28,F28<M28,F28<N28),"Yes","No") -> Yes
D29: 22 | E29: #VALUE! | F29: {=_FV(E29,"Price")} -> 80.01 | G29: {=_FV(E29,"52 week high",TRUE)} -> 99.459 | H29: {=_FV(E29,"52 week low",TRUE)} -> 56.4 | I29: {=_FV(E29,"P/E",TRUE)} -> 23.2263 | O29: =IF(AND(F29<K29,F29<L29,F29<M29,F29<N29),"Yes","No") -> No
D30: 23 | E30: #VALUE! | F30: {=_FV(E30,"Price")} -> 64.8 | G30: {=_FV(E30,"52 week high",TRUE)} -> 71.7081 | H30: {=_FV(E30,"52 week low",TRUE)} -> 50.49 | I30: {=_FV(E30,"P/E",TRUE)} -> 13.7298 | O30: =IF(AND(F30<K30,F30<L30,F30<M30,F30<N30),"Yes","No") -> No
